Workbook

Sheet Sheet1
B1: Name | C1: Category | D1: Product Name | E1: Region | F1: City | G1: State | H1: Gender | I1: Price | J1: amaunt | M1: North | N1: Delhi | O1: Delhi
B2: Bharat Innovations | C2: Electronic | D2: Speaker | E2: North | F2: Delhi | G2: Delhi | H2: Male | I2: 4292 | J2: 3360636 | M2: West | N2: Mumbai | O2: Maharashtra
B3: Green Leaf Enterprises | C3: Electronic | D3: Car accessories | E3: West | F3: Mumbai | G3: Maharashtra | H3: Male | I3: 8037 | J3: 4645386 | M3: East | N3: Kolkata | O3: West Bengal
B4: Urban Pulse Technologies | C4: Electronic | D4: Earbuds | E4: East | F4: Kolkata | G4: West Bengal | H4: Male | I4: 2415 | J4: 1523865 | M4: South | N4: Chennai | O4: Tamil Nadu
B5: Mystic India Exports | C5: Electronic | D5: Earbuds | E5: South | F5: Chennai | G5: Tamil Nadu | H5: Male | I5: 3941 | J5: 3566605 | L5: Chennai | M5: Central | N5: Bengaluru | O5: Karnataka
B6: Golden Horizon Ventures | C6: Fashion | D6: Women dress | E6: South | F6: Bengaluru | G6: Karnataka | H6: Male | I6: 4607 | J6: 4064994 | N6: Hyderabad | O6: Telangana
B7: Eternal Traditions | C7: Fashion | D7: Women dress | E7: South | F7: Hyderabad | G7: Telangana | H7: Male | I7: 4261 | J7: 4064994 | N7: Ahmedabad | O7: Gujarat
B8: Apex Solutions | C8: Fashion | D8: Speaker | E8: West | F8: Ahmedabad | G8: Gujarat | H8: Male | I8: 9084 | J8: 5541240 | M8: Northeast | N8: Pune | O8: Rajasthan
B9: Harmony Foods | C9: Fashion | D9: Women dress | E9: West | F9: Pune | G9: Maharashtra | H9: Male | I9: 6694 | J9: 4966948 | M9: North (UT) | N9: Jaipur | O9: Uttar Pradesh
B10: Pure Essence Skincare | C10: Electronic | D10: Product Name | E10: North | F10: Jaipur | G10: Rajasthan | H10: Female | I10: 2678 | J10: 1518426 | N10: Surat
B11: Zenith Construction Co. | C11: Electronic | D11: Speaker | E11: West | F11: Surat | G11: Gujarat | H11: Female | I11: 1631 | J11: 828548 | N11: Lucknow | O11: Madhya Pradesh
B12: Radiant Health Systems | C12: Electronic | D12: Speaker | E12: West | F12: Lucknow | G12: Uttar Pradesh | H12: Female | I12: 4171 | J12: 2681953 | N12: Kanpur | O12: State
B13: Divine Creations | C13: Electronic | D13: Speaker | E13: North | F13: Kanpur | G13: Uttar Pradesh | H13: Female | I13: 4283 | J13: 3443532 | N13: Nagpur | O13: Assam
B14: Metro Tech Solutions | C14: Electronic | D14: speaker | E14: West | F14: Nagpur | H14: Female | I14: 4249 | J14: 3577658 | N14: Indore | O14: Punjab
B15: True Path Logistics | C15: Electronic | D15: Speaker | E15: Central | F15: Indore | G15: Madhya Pradesh | H15: Female | I15: 1902 | J15: 1276242 | N15: Vadodara | O15: Chhattisgarh
B16: Classic Cuisines | C16: Fashion | D16: Male dress | E16: West | F16: Vadodara | G16: Gujarat | H16: Male | I16: 5603 | J16: 5512404 | N16: Agra | O16: Jharkhand
B17: Bold Ventures | C17: Fashion | D17: Male dress | E17: North | F17: Agra | G17: Uttar Pradesh | H17: Male | I17: 9513 | J17: 1984929 | N17: Meerut | O17: Chandigarh
B18: Prestige Automobiles | C18: Electronic | D18: TV | E18: North | F18: Meerut | G18: Uttar Pradesh | H18: Male | I18: 9633 | J18: 3014882 | N18: Coimbatore | O18: Andhra Pradesh
B19: Elite Marketing Solutions | C19: Electronic | D19: TV | E19: South | F19: Coimbatore | G19: Tamil Nadu | H19: Male | I19: 4332 | J19: 4510462 | N19: Madurai | O19: Bihar
B20: Natural Bliss Beverages | C20: Decor | D20: TV | E20: South | F20: Madurai | G20: Tamil Nadu | H20: Male | I20: 1995 | J20: 5389631 | N20: City | O20: Kerala
B21: Bharat Innovations | C21: Electronic | D21: Speaker | E21: North | F21: Delhi | G21: Delhi | H21: Male | I21: 5111 | J21: 6012216 | N21: Guwahati | O21: Himachal Pradesh
B22: Green Leaf Enterprises | C22: Electronic | D22: Car accessories | E22: West | F22: Mumbai | G22: Maharashtra | H22: Male | I22: 5131 | J22: 8583003 | N22: Amritsar | O22: Uttarakhand
B23: Urban Pulse Technologies | C23: Electronic | D23: Earbuds | E23: East | F23: Kolkata | G23: West Bengal | H23: Male | I23: 5151 | J23: 3716856 | N23: Raipur | O23: palestine
B24: Mystic India Exports | C24: Electronic | D24: Earbuds | E24: South | F24: Chennai | G24: Tamil Nadu | H24: Male | I24: 5171 | J24: 1789515 | N24: Durgapur
B25: Golden Horizon Ventures | C25: Fashion | D25: Women dress | E25: South | F25: Bengaluru | G25: Karnataka | H25: Male | I25: 5191 | J25: 3469540 | N25: Gwalior
B26: Eternal Traditions | C26: Fashion | D26: Women dress | E26: South | F26: Hyderabad | G26: Telangana | H26: Male | I26: 5210 | J26: 1809280 | N26: Jamshedpur
B27: Apex Solutions | C27: Fashion | D27: Woman dress | E27: West | F27: Ahmedabad | G27: Gujarat | H27: Male | I27: 5230 | J27: 2869344 | N27: Siliguri
B28: Harmony Foods | C28: Fashion | D28: Women dress | E28: West | F28: Pune | G28: Maharashtra | H28: Male | I28: 5250 | J28: 1071696 | N28: Mangalore
B29: Pure Essence Skincare | C29: Electronic | D29: Speaker | E29: North | F29: Jaipur | G29: Rajasthan | H29: Female | I29: 5270 | J29: 2180250 | N29: Thane
B30: Zenith Construction Co. | C30: Electronic | D30: Speaker | E30: West | F30: Surat | G30: Gujarat | H30: Female | I30: 5290 | J30: 1638288 | N30: Chandigarh
B31: Radiant Health Systems | C31: Electronic | D31: Speaker | E31: q | F31: Lucknow | G31: Uttar Pradesh | H31: Female | I31: 5310 | J31: 1425416 | N31: Bhopal
B32: Divine Creations | C32: Electronic | D32: Speaker | E32: North | F32: Kanpur | G32: Uttar Pradesh | H32: Female | I32: 5330 | J32: 1815030 | N32: Visakhapatnam
B33: Metro Tech Solutions | C33: Electronic | D33: speaker | E33: West | F33: Nagpur | G33: Maharashtra | H33: Female | I33: 5350 | J33: 6327892 | N33: Patna
B34: True Path Logistics | C34: Electronic | D34: Speaker | E34: Central | F34: Indore | G34: Madhya Pradesh | H34: Female | I34: 5370 | J34: 6102567 | N34: Jodhpur
B35: Classic Cuisines | C35: Fashion | D35: Male dress | E35: West | F35: Vadodara | G35: Gujarat | H35: Male | I35: 5390 | J35: 2619594 | N35: Varanasi
... B40: Urban Pulse Technologies | C40: Electronic | D40: Earbuds | E40: East | F40: Kolkata | G40: West Bengal | H40: Male | I40: 5151 | J40: 3619671 | N40: Dehradun
B41: Mystic India Exports | C41: Electronic | D41: Earbuds | E41: South | F41: Chennai | G41: Tamil Nadu | H41: Male | I41: 5171 | J41: 7726806
B42: Golden Horizon Ventures | C42: Fashion | D42: Women dress | E42: South | F42: Bengaluru | G42: Karnataka | H42: Male | I42: 5191 | J42: 4226591
B43: Eternal Traditions | C43: Fashion | D43: Women dress | E43: South | F43: Hyderabad | G43: Telangana | H43: Male | I43: 5210 | J43: 5273215
B44: Apex Solutions | C44: Fashion | D44: ss | E44: West | F44: Ahmedabad | G44: Gujarat | H44: Male | I44: 5230 | J44: 4131849
...

Sheet Sheet3
C2: sales | I2: CATEGORY | O2: PRODUCT NAME
C3: TARGET | D3: =Sheet2!D318 -> 2.2554581e+09 | E3: =D3/D5 -> 0.62944092 | I3: Electronic | J3: =SUMIF(Sheet1!C1:C320,I3,Sheet1!J1:J320) -> 714285428 | K3: =J3/J6 -> 0.54125784 | O3: Speaker | P3: =SUMIF(Sheet1!D2:D320,Sheet3!O3,Sheet1!J2:J320) -> 317283846 | Q3: =P3/P13 -> 0.24967098
C4: ACTUAL | D4: =SUM(Sheet1!J2:J320) -> 1327814011 | E4: =D4/D5 -> 0.37055908 | G4: =F4/F5 -> #DIV/0! | I4: Decor | J4: =SUMIF(Sheet1!C2:C321,Sheet1!C8,Sheet1!J2:J321) -> 508084809 | K4: =J4/J6 -> 0.385007 | O4: Car accessories | P4: =SUMIF(Sheet1!D3:D321,Sheet3!O4,Sheet1!J3:J321) -> 95807748 | Q4: =P4/P13 -> 0.075391213
C5: TOTAL | D5: =SUM(D3:D4) -> 3.5832721e+09 | I5: Fashion | J5: =SUMIF(Sheet1!C3:C322,Sheet1!C20,Sheet1!J3:J322) -> 97306586 | K5: =J5/J6 -> 0.073735163 | O5: Earbuds | P5: =SUMIF(Sheet1!D4:D322,Sheet3!O5,Sheet1!J4:J322) -> 103337980 | Q5: =P5/P13 -> 0.08131676
I6: TOTAL | J6: =SUM(J3:J5) -> 1319676823 | O6: Women dress | P6: =SUMIF(Sheet1!D5:D323,Sheet3!O6,Sheet1!J5:J323) -> 155228972 | Q6: =P6/P13 -> 0.12214983
O7: Male dress | P7: =SUMIF(Sheet1!D6:D324,Sheet3!O7,Sheet1!J6:J324) -> 102125422 | Q7: =P7/P13 -> 0.080362597
O8: TV | P8: =SUMIF(Sheet1!D7:D325,Sheet3!O8,Sheet1!J7:J325) -> 144374534 | Q8: =P8/P13 -> 0.11360847
C9: REGION | I9: CITY | O9: Laptop | P9: =SUMIF(Sheet1!D8:D326,Sheet3!O9,Sheet1!J8:J326) -> 94919158 | Q9: =P9/P13 -> 0.07469198
C10: North | D10: =SUMIF(Sheet1!E2:E320,Sheet3!C10,Sheet1!J2:J320) -> 375404654 | E10: =D10/D17 -> 0.29045849 | I10: Delhi | J10: =SUMIF(Sheet1!F2:F320,Sheet3!I10,Sheet1!J2:J320) -> 61855291 | K10: =J10/J49 -> 0.046871545 | O10: Saree | P10: =SUMIF(Sheet1!D9:D327,Sheet3!O10,Sheet1!J9:J327) -> 127282366 | Q10: =P10/P13 -> 0.10015862
C11: West | D11: =SUMIF(Sheet1!E3:E321,Sheet3!C11,Sheet1!J3:J321) -> 343923358 | E11: =D11/D17 -> 0.26610075 | I11: Mumbai | J11: =SUMIF(Sheet1!F3:F321,Sheet3!I11,Sheet1!J3:J321) -> 72543594 | K11: =J11/J49 -> 0.054970727 | O11: Suit | P11: =SUMIF(Sheet1!D10:D328,Sheet3!O11,Sheet1!J10:J328) -> 70556301 | Q11: =P11/P13 -> 0.055520824
C12: East | D12: =SUMIF(Sheet1!E4:E322,Sheet3!C12,Sheet1!J4:J322) -> 139290434 | E12: =D12/D17 -> 0.10777194 | I12: Kolkata | J12: =SUMIF(Sheet1!F4:F322,Sheet3!I12,Sheet1!J4:J322) -> 68735509 | K12: =J12/J49 -> 0.052085107 | O12: Home décor | P12: =SUMIF(Sheet1!D11:D329,Sheet3!O12,Sheet1!J11:J329) -> 59891562 | Q12: =P12/P13 -> 0.04712873
C13: South | D13: =SUMIF(Sheet1!E5:E323,Sheet3!C13,Sheet1!J5:J323) -> 293625942 | E13: =D13/D17 -> 0.22718458 | I13: Chennai | J13: =SUMIF(Sheet1!F5:F323,Sheet3!I13,Sheet1!J5:J323) -> 60699620 | K13: =J13/J49 -> 0.045995822 | O13: TOTAL | P13: =SUM(P3:P12) -> 1270807889
C14: Central | D14: =SUMIF(Sheet1!E6:E324,Sheet3!C14,Sheet1!J6:J324) -> 113674373 | E14: =D14/D17 -> 0.087952259 | I14: Bengaluru | J14: =SUMIF(Sheet1!F6:F324,Sheet3!I14,Sheet1!J6:J324) -> 57782428 | K14: =J14/J49 -> 0.043785287
C15: Northeast | D15: =SUMIF(Sheet1!E7:E325,Sheet3!C15,Sheet1!J7:J325) -> 25120992 | E15: =D15/D17 -> 0.019436641 | I15: Hyderabad | J15: =SUMIF(Sheet1!F7:F325,Sheet3!I15,Sheet1!J7:J325) -> 58891853 | K15: =J15/J49 -> 0.044625966
C16: North (UT) | D16: =SUMIF(Sheet1!E8:E326,Sheet3!C16,Sheet1!J8:J326) -> 1415664 | E16: =D16/D17 -> 0.0010953291 | F16: STATE | I16: Ahmedabad | J16: =SUMIF(Sheet1!F8:F326,Sheet3!I16,Sheet1!J8:J326) -> 58932728 | K16: =J16/J49 -> 0.044656939
C17: TOTAL | D17: =SUM(D10:D16) -> 1292455417 | F17: Delhi | G17: =SUMIF(Sheet1!G2:G320,Sheet3!F17,Sheet1!J2:J320) -> 61855291 | H17: =G17/G38 -> 0.046998959 | I17: Pune | J17: =SUMIF(Sheet1!F9:F327,Sheet3!I17,Sheet1!J9:J327) -> 49147370 | K17: =J17/J49 -> 0.037241974
F18: Maharashtra | G18: =SUMIF(Sheet1!G3:G321,Sheet3!F18,Sheet1!J3:J321) -> 189861417 | H18: =G18/G38 -> 0.14426072 | I18: Jaipur | J18: =SUMIF(Sheet1!F10:F328,Sheet3!I18,Sheet1!J10:J328) -> 35764610 | K18: =J18/J49 -> 0.027101037
F19: West Bengal | G19: =SUMIF(Sheet1!G4:G322,Sheet3!F19,Sheet1!J4:J322) -> 95724317 | H19: =G19/G38 -> 0.072733362 | I19: Surat | J19: =SUMIF(Sheet1!F11:F329,Sheet3!I19,Sheet1!J11:J329) -> 34908225 | K19: =J19/J49 -> 0.026452101
F20: Tamil Nadu | G20: =SUMIF(Sheet1!G5:G323,Sheet3!F20,Sheet1!J5:J323) -> 134752949 | H20: =G20/G38 -> 0.10238814 | I20: Lucknow | J20: =SUMIF(Sheet1!F12:F330,Sheet3!I20,Sheet1!J12:J330) -> 30957279 | K20: =J20/J49 -> 0.023458227
B21: GENDER | F21: Karnataka | G21: =SUMIF(Sheet1!G6:G324,Sheet3!F21,Sheet1!J6:J324) -> 73505492 | H21: =G21/G38 -> 0.055851029 | I21: Kanpur | J21: =SUMIF(Sheet1!F13:F331,Sheet3!I21,Sheet1!J13:J331) -> 44875052 | K21: =J21/J49 -> 0.034004577
B22: MALE | C22: =SUMIF(Sheet1!H2:H320,Sheet3!B22,Sheet1!J2:J320) -> 809895418 | D22: =C22/C24 -> 0.61463357 | F22: Telangana | G22: =SUMIF(Sheet1!G7:G325,Sheet3!F22,Sheet1!J7:J325) -> 58891853 | H22: =G22/G38 -> 0.044747276 | I22: Nagpur | J22: =SUMIF(Sheet1!F14:F332,Sheet3!I22,Sheet1!J14:J332) -> 46415286 | K22: =J22/J49 -> 0.035171707
B23: FEMALE | C23: =SUMIF(Sheet1!H3:H321,Sheet3!B23,Sheet1!J3:J321) -> 507792805 | D23: =C23/C24 -> 0.38536643 | F23: Gujarat | G23: =SUMIF(Sheet1!G8:G326,Sheet3!F23,Sheet1!J8:J326) -> 140356520 | H23: =G23/G38 -> 0.10664585 | I23: Indore | J23: =SUMIF(Sheet1!F15:F333,Sheet3!I23,Sheet1!J15:J333) -> 57552650 | K23: =J23/J49 -> 0.04361117
B24: TOTAL | C24: =SUM(C22:C23) -> 1317688223 | F24: Rajasthan | G24: =SUMIF(Sheet1!G9:G327,Sheet3!F24,Sheet1!J9:J327) -> 48895100 | H24: =G24/G38 -> 0.037151532 | I24: Vadodara | J24: =SUMIF(Sheet1!F16:F334,Sheet3!I24,Sheet1!J16:J334) -> 46515567 | K24: =J24/J49 -> 0.035247696
F25: Uttar Pradesh | G25: =SUMIF(Sheet1!G10:G328,Sheet3!F25,Sheet1!J10:J328) -> 208685928 | H25: =G25/G38 -> 0.15856398 | I25: Agra | J25: =SUMIF(Sheet1!F17:F335,Sheet3!I25,Sheet1!J17:J335) -> 49285056 | K25: =J25/J49 -> 0.037346307
F26: Madhya Pradesh | G26: =SUMIF(Sheet1!G11:G329,Sheet3!F26,Sheet1!J11:J329) -> 85696717 | H26: =G26/G38 -> 0.065114179 | I26: Meerut | J26: =SUMIF(Sheet1!F18:F336,Sheet3!I26,Sheet1!J18:J336) -> 62231175 | K26: =J26/J49 -> 0.047156375
F27: Assam | G27: =SUMIF(Sheet1!G12:G330,Sheet3!F27,Sheet1!J12:J330) -> 25120992 | H27: =G27/G38 -> 0.019087461 | I27: Coimbatore | J27: =SUMIF(Sheet1!F19:F337,Sheet3!I27,Sheet1!J19:J337) -> 35088604 | K27: =J27/J49 -> 0.026588786
F28: Punjab | G28: =SUMIF(Sheet1!G13:G331,Sheet3!F28,Sheet1!J13:J331) -> 38884285 | H28: =G28/G38 -> 0.029545103 | I28: Madurai | J28: =SUMIF(Sheet1!F20:F338,Sheet3!I28,Sheet1!J20:J338) -> 38964725 | K28: =J28/J49 -> 0.02952596
F29: Chhattisgarh | G29: =SUMIF(Sheet1!G14:G332,Sheet3!F29,Sheet1!J14:J332) -> 27977656 | H29: =G29/G38 -> 0.021258015 | I29: Guwahati | J29: =SUMIF(Sheet1!F21:F339,Sheet3!I29,Sheet1!J21:J339) -> 25120992 | K29: =J29/J49 -> 0.019035715
F30: Jharkhand | G30: =SUMIF(Sheet1!G15:G333,Sheet3!F30,Sheet1!J15:J333) -> 39650597 | H30: =G30/G38 -> 0.030127363 | I30: Amritsar | J30: =SUMIF(Sheet1!F22:F340,Sheet3!I30,Sheet1!J22:J340) -> 38884285 | K30: =J30/J49 -> 0.029465006
F31: Chandigarh | G31: =SUMIF(Sheet1!G16:G334,Sheet3!F31,Sheet1!J16:J334) -> 1415664 | H31: =G31/G38 -> 0.0010756515 | I31: Raipur | J31: =SUMIF(Sheet1!F23:F341,Sheet3!I31,Sheet1!J23:J341) -> 27977656 | K31: =J31/J49 -> 0.021200384
F32: Andhra Pradesh | G32: =SUMIF(Sheet1!G17:G335,Sheet3!F32,Sheet1!J17:J335) -> 4425484 | H32: =G32/G38 -> 0.0033625764 | I32: Durgapur | J32: =SUMIF(Sheet1!F24:F342,Sheet3!I32,Sheet1!J24:J342) -> 16845582 | K32: =J32/J49 -> 0.01276493
F33: Bihar | G33: =SUMIF(Sheet1!G18:G336,Sheet3!F33,Sheet1!J18:J336) -> 3915520 | H33: =G33/G38 -> 0.002975095 | I33: Gwalior | J33: =SUMIF(Sheet1!F25:F343,Sheet3!I33,Sheet1!J25:J343) -> 25652066 | K33: =J33/J4 -> 0.050487764
F34: Kerala | G34: =SUMIF(Sheet1!G19:G337,Sheet3!F34,Sheet1!J19:J337) -> 22050164 | H34: =G34/G38 -> 0.016754181 | I34: Jamshedpur | J34: =SUMIF(Sheet1!F26:F344,Sheet3!I34,Sheet1!J26:J344) -> 18313462 | K34: =J34/J49 -> 0.013877232
F35: Himachal Pradesh | G35: =SUMIF(Sheet1!G20:G338,Sheet3!F35,Sheet1!J20:J338) -> 20220048 | H35: =G35/G38 -> 0.01536362 | I35: Siliguri | J35: =SUMIF(Sheet1!F27:F345,Sheet3!I35,Sheet1!J27:J345) -> 10143226 | K35: =J35/J49 -> 0.0076861439
F36: Uttarakhand | G36: =SUMIF(Sheet1!G21:G339,Sheet3!F36,Sheet1!J21:J339) -> 26767361 | H36: =G36/G38 -> 0.020338407 | I36: Mangalore | J36: =SUMIF(Sheet1!F28:F346,Sheet3!I36,Sheet1!J28:J346) -> 15723064 | K36: =J36/J49 -> 0.011914329
F37: palestine | G37: =SUMIF(Sheet1!G22:G340,Sheet3!F37,Sheet1!J22:J340) -> 7445810 | H37: =G37/G38 -> 0.005657484 | I37: Thane | J37: =SUMIF(Sheet1!F29:F347,Sheet3!I37,Sheet1!J29:J347) -> 4920480 | K37: =J37/J49 -> 0.0037285492
F38: TOTAL | G38: =SUM(G17:G37) -> 1316099165 | I38: Chandigarh | J38: =SUMIF(Sheet1!F30:F348,Sheet3!I38,Sheet1!J30:J348) -> 1415664 | K38: =J38/J49 -> 0.0010727354
I39: Bhopal | J39: =SUMIF(Sheet1!F31:F349,Sheet3!I39,Sheet1!J31:J349) -> 2492001 | K39: =J39/J49 -> 0.0018883419
I40: Visakhapatnam | J40: =SUMIF(Sheet1!F32:F350,Sheet3!I40,Sheet1!J32:J350) -> 4425484 | K40: =J40/J49 -> 0.0033534604
I41: Patna | J41: =SUMIF(Sheet1!F33:F351,Sheet3!I41,Sheet1!J33:J351) -> 3915520 | K41: =J41/J49 -> 0.0029670295
...

Sheet DASHBOARD

Sheet Sheet6

Sheet Sheet2
A1: Name | B1: Quantity | C1: Rate | D1: Amount
A2: Bharat Innovations | B2: 3305 | C2: 890 | D2: 2941450
A3: Green Leaf Enterprises | B3: 2224 | C3: 761 | D3: 1692464 | E3: VSVS
A4: Urban Pulse Technologies | B4: 3349 | C4: 1383 | D4: 4631667
A5: Mystic India Exports | B5: 2941 | C5: 865 | D5: 2543965
A6: Golden Horizon Ventures | B6: 6908 | C6: 1939 | D6: 13394612
A7: Eternal Traditions | B7: 10555 | C7: 404 | D7: 4264220
A8: Apex Solutions | B8: 4773 | C8: 1241 | D8: 5923293
A9: Harmony Foods | B9: 1432 | C9: 1935 | D9: 2770920
A10: Pure Essence Skincare | B10: 7186 | C10: 915 | D10: 6575190
A11: Zenith Construction Co. | B11: 9072 | C11: 1154 | D11: 10469088
A12: Radiant Health Systems | B12: 10480 | C12: 646 | D12: 6770080
A13: Divine Creations | B13: 10827 | C13: 1482 | D13: 16045614
A14: Metro Tech Solutions | B14: 2753 | C14: 755 | D14: 2078515
A15: True Path Logistics | B15: 10390 | C15: 1369 | D15: 14223910
... A317: Radiant Solutions Co. | B317: 9526 | C317: 482 | D317: 4591532
D318: =SUM(D2:D317) -> 2.2554581e+09
